Last login: Sun Oct 15 09:27:20 on ttys000
Catalinas-MacBook-Pro:~ catalinaene$ cd desktop
Catalinas-MacBook-Pro:desktop catalinaene$ cd myEnvironments
Catalinas-MacBook-Pro:myEnvironments catalinaene$ source djangoEnv/bin/activate
(djangoEnv) Catalinas-MacBook-Pro:myEnvironments catalinaene$ cd ..
(djangoEnv) Catalinas-MacBook-Pro:desktop catalinaene$ cd Assignments
(djangoEnv) Catalinas-MacBook-Pro:Assignments catalinaene$ cd PythonStack
(djangoEnv) Catalinas-MacBook-Pro:PythonStack catalinaene$ cd Django
(djangoEnv) Catalinas-MacBook-Pro:Django catalinaene$ ls
Cats_Project	Random_Word	Users
Django		Surveys		time_and_date
(djangoEnv) Catalinas-MacBook-Pro:Django catalinaene$ cd USers
(djangoEnv) Catalinas-MacBook-Pro:USers catalinaene$ ls
Users		apps		db.sqlite3	manage.py
(djangoEnv) Catalinas-MacBook-Pro:USers catalinaene$ python manage.py makemigrations
Migrations for 'users_app':
  apps/users_app/migrations/0001_initial.py
    - Create model user
(djangoEnv) Catalinas-MacBook-Pro:USers catalinaene$ python manage.py

Type 'manage.py help <subcommand>' for help on a specific subcommand.

Available subcommands:

[auth]
    changepassword
    createsuperuser

[contenttypes]
    remove_stale_contenttypes

[django]
    check
    compilemessages
    createcachetable
    dbshell
    diffsettings
    dumpdata
    flush
    inspectdb
    loaddata
    makemessages
    makemigrations
    migrate
    sendtestemail
    shell
    showmigrations
    sqlflush
    sqlmigrate
    sqlsequencereset
    squashmigrations
    startapp
    startproject
    test
    testserver

[sessions]
    clearsessions

[staticfiles]
    collectstatic
    findstatic
    runserver
(djangoEnv) Catalinas-MacBook-Pro:USers catalinaene$ python manage.py shell
Python 2.7.10 (default, Feb  7 2017, 00:08:15) 
[GCC 4.2.1 Compatible Apple LLVM 8.0.0 (clang-800.0.34)] on darwin
Type "help", "copyright", "credits" or "license" for more information.
(InteractiveConsole)
>>> from apps.users_app.models import *
>>> b = user(first_name="Catalina",last_name="Ene",email_address="cat@gmail.com",age="24")
>>> b.save
<bound method user.save of <user: user object>>
>>> b = user.objects.first()
Traceback (most recent call last):
  File "<console>", line 1, in <module>
  File "/Users/catalinaene/Desktop/myEnvironments/djangoEnv/lib/python2.7/site-packages/django/db/models/manager.py", line 85, in manager_method
    return getattr(self.get_queryset(), name)(*args, **kwargs)
  File "/Users/catalinaene/Desktop/myEnvironments/djangoEnv/lib/python2.7/site-packages/django/db/models/query.py", line 564, in first
    objects = list((self if self.ordered else self.order_by('pk'))[:1])
  File "/Users/catalinaene/Desktop/myEnvironments/djangoEnv/lib/python2.7/site-packages/django/db/models/query.py", line 250, in __iter__
    self._fetch_all()
  File "/Users/catalinaene/Desktop/myEnvironments/djangoEnv/lib/python2.7/site-packages/django/db/models/query.py", line 1118, in _fetch_all
    self._result_cache = list(self._iterable_class(self))
  File "/Users/catalinaene/Desktop/myEnvironments/djangoEnv/lib/python2.7/site-packages/django/db/models/query.py", line 53, in __iter__
    results = compiler.execute_sql(chunked_fetch=self.chunked_fetch)
  File "/Users/catalinaene/Desktop/myEnvironments/djangoEnv/lib/python2.7/site-packages/django/db/models/sql/compiler.py", line 894, in execute_sql
    raise original_exception
OperationalError: no such table: users_app_user
>>> user.object.all()
Traceback (most recent call last):
  File "<console>", line 1, in <module>
AttributeError: type object 'user' has no attribute 'object'
>>> user.objects.all()
Traceback (most recent call last):
  File "<console>", line 1, in <module>
  File "/Users/catalinaene/Desktop/myEnvironments/djangoEnv/lib/python2.7/site-packages/django/db/models/query.py", line 226, in __repr__
    data = list(self[:REPR_OUTPUT_SIZE + 1])
  File "/Users/catalinaene/Desktop/myEnvironments/djangoEnv/lib/python2.7/site-packages/django/db/models/query.py", line 250, in __iter__
    self._fetch_all()
  File "/Users/catalinaene/Desktop/myEnvironments/djangoEnv/lib/python2.7/site-packages/django/db/models/query.py", line 1118, in _fetch_all
    self._result_cache = list(self._iterable_class(self))
  File "/Users/catalinaene/Desktop/myEnvironments/djangoEnv/lib/python2.7/site-packages/django/db/models/query.py", line 53, in __iter__
    results = compiler.execute_sql(chunked_fetch=self.chunked_fetch)
  File "/Users/catalinaene/Desktop/myEnvironments/djangoEnv/lib/python2.7/site-packages/django/db/models/sql/compiler.py", line 894, in execute_sql
    raise original_exception
OperationalError: no such table: users_app_user
>>> users.objects.all()
Traceback (most recent call last):
  File "<console>", line 1, in <module>
NameError: name 'users' is not defined
>>> user.objects.create(first_name="Catalina")
Traceback (most recent call last):
  File "<console>", line 1, in <module>
  File "/Users/catalinaene/Desktop/myEnvironments/djangoEnv/lib/python2.7/site-packages/django/db/models/manager.py", line 85, in manager_method
    return getattr(self.get_queryset(), name)(*args, **kwargs)
  File "/Users/catalinaene/Desktop/myEnvironments/djangoEnv/lib/python2.7/site-packages/django/db/models/query.py", line 394, in create
    obj.save(force_insert=True, using=self.db)
  File "/Users/catalinaene/Desktop/myEnvironments/djangoEnv/lib/python2.7/site-packages/django/db/models/base.py", line 808, in save
    force_update=force_update, update_fields=update_fields)
  File "/Users/catalinaene/Desktop/myEnvironments/djangoEnv/lib/python2.7/site-packages/django/db/models/base.py", line 838, in save_base
    updated = self._save_table(raw, cls, force_insert, force_update, using, update_fields)
  File "/Users/catalinaene/Desktop/myEnvironments/djangoEnv/lib/python2.7/site-packages/django/db/models/base.py", line 924, in _save_table
    result = self._do_insert(cls._base_manager, using, fields, update_pk, raw)
  File "/Users/catalinaene/Desktop/myEnvironments/djangoEnv/lib/python2.7/site-packages/django/db/models/base.py", line 963, in _do_insert
    using=using, raw=raw)
  File "/Users/catalinaene/Desktop/myEnvironments/djangoEnv/lib/python2.7/site-packages/django/db/models/manager.py", line 85, in manager_method
    return getattr(self.get_queryset(), name)(*args, **kwargs)
  File "/Users/catalinaene/Desktop/myEnvironments/djangoEnv/lib/python2.7/site-packages/django/db/models/query.py", line 1076, in _insert
    return query.get_compiler(using=using).execute_sql(return_id)
  File "/Users/catalinaene/Desktop/myEnvironments/djangoEnv/lib/python2.7/site-packages/django/db/models/sql/compiler.py", line 1107, in execute_sql
    cursor.execute(sql, params)
  File "/Users/catalinaene/Desktop/myEnvironments/djangoEnv/lib/python2.7/site-packages/django/db/backends/utils.py", line 80, in execute
    return super(CursorDebugWrapper, self).execute(sql, params)
  File "/Users/catalinaene/Desktop/myEnvironments/djangoEnv/lib/python2.7/site-packages/django/db/backends/utils.py", line 65, in execute
    return self.cursor.execute(sql, params)
  File "/Users/catalinaene/Desktop/myEnvironments/djangoEnv/lib/python2.7/site-packages/django/db/utils.py", line 94, in __exit__
    six.reraise(dj_exc_type, dj_exc_value, traceback)
  File "/Users/catalinaene/Desktop/myEnvironments/djangoEnv/lib/python2.7/site-packages/django/db/backends/utils.py", line 65, in execute
    return self.cursor.execute(sql, params)
  File "/Users/catalinaene/Desktop/myEnvironments/djangoEnv/lib/python2.7/site-packages/django/db/backends/sqlite3/base.py", line 328, in execute
    return Database.Cursor.execute(self, query, params)
OperationalError: no such table: users_app_user
>>> user.objects.create(first_name="catalina")
Traceback (most recent call last):
  File "<console>", line 1, in <module>
  File "/Users/catalinaene/Desktop/myEnvironments/djangoEnv/lib/python2.7/site-packages/django/db/models/manager.py", line 85, in manager_method
    return getattr(self.get_queryset(), name)(*args, **kwargs)
  File "/Users/catalinaene/Desktop/myEnvironments/djangoEnv/lib/python2.7/site-packages/django/db/models/query.py", line 394, in create
    obj.save(force_insert=True, using=self.db)
  File "/Users/catalinaene/Desktop/myEnvironments/djangoEnv/lib/python2.7/site-packages/django/db/models/base.py", line 808, in save
    force_update=force_update, update_fields=update_fields)
  File "/Users/catalinaene/Desktop/myEnvironments/djangoEnv/lib/python2.7/site-packages/django/db/models/base.py", line 838, in save_base
    updated = self._save_table(raw, cls, force_insert, force_update, using, update_fields)
  File "/Users/catalinaene/Desktop/myEnvironments/djangoEnv/lib/python2.7/site-packages/django/db/models/base.py", line 924, in _save_table
    result = self._do_insert(cls._base_manager, using, fields, update_pk, raw)
  File "/Users/catalinaene/Desktop/myEnvironments/djangoEnv/lib/python2.7/site-packages/django/db/models/base.py", line 963, in _do_insert
    using=using, raw=raw)
  File "/Users/catalinaene/Desktop/myEnvironments/djangoEnv/lib/python2.7/site-packages/django/db/models/manager.py", line 85, in manager_method
    return getattr(self.get_queryset(), name)(*args, **kwargs)
  File "/Users/catalinaene/Desktop/myEnvironments/djangoEnv/lib/python2.7/site-packages/django/db/models/query.py", line 1076, in _insert
    return query.get_compiler(using=using).execute_sql(return_id)
  File "/Users/catalinaene/Desktop/myEnvironments/djangoEnv/lib/python2.7/site-packages/django/db/models/sql/compiler.py", line 1107, in execute_sql
    cursor.execute(sql, params)
  File "/Users/catalinaene/Desktop/myEnvironments/djangoEnv/lib/python2.7/site-packages/django/db/backends/utils.py", line 80, in execute
    return super(CursorDebugWrapper, self).execute(sql, params)
  File "/Users/catalinaene/Desktop/myEnvironments/djangoEnv/lib/python2.7/site-packages/django/db/backends/utils.py", line 65, in execute
    return self.cursor.execute(sql, params)
  File "/Users/catalinaene/Desktop/myEnvironments/djangoEnv/lib/python2.7/site-packages/django/db/utils.py", line 94, in __exit__
    six.reraise(dj_exc_type, dj_exc_value, traceback)
  File "/Users/catalinaene/Desktop/myEnvironments/djangoEnv/lib/python2.7/site-packages/django/db/backends/utils.py", line 65, in execute
    return self.cursor.execute(sql, params)
  File "/Users/catalinaene/Desktop/myEnvironments/djangoEnv/lib/python2.7/site-packages/django/db/backends/sqlite3/base.py", line 328, in execute
    return Database.Cursor.execute(self, query, params)
OperationalError: no such table: users_app_user
>>> 
KeyboardInterrupt
>>> wxit
Traceback (most recent call last):
  File "<console>", line 1, in <module>
NameError: name 'wxit' is not defined
>>> exit
Use exit() or Ctrl-D (i.e. EOF) to exit
>>> exit()
(djangoEnv) Catalinas-MacBook-Pro:USers catalinaene$ python manage.py makemigrations
Traceback (most recent call last):
  File "manage.py", line 22, in <module>
    execute_from_command_line(sys.argv)
  File "/Users/catalinaene/Desktop/myEnvironments/djangoEnv/lib/python2.7/site-packages/django/core/management/__init__.py", line 364, in execute_from_command_line
    utility.execute()
  File "/Users/catalinaene/Desktop/myEnvironments/djangoEnv/lib/python2.7/site-packages/django/core/management/__init__.py", line 356, in execute
    self.fetch_command(subcommand).run_from_argv(self.argv)
  File "/Users/catalinaene/Desktop/myEnvironments/djangoEnv/lib/python2.7/site-packages/django/core/management/base.py", line 283, in run_from_argv
    self.execute(*args, **cmd_options)
  File "/Users/catalinaene/Desktop/myEnvironments/djangoEnv/lib/python2.7/site-packages/django/core/management/base.py", line 327, in execute
    self.check()
  File "/Users/catalinaene/Desktop/myEnvironments/djangoEnv/lib/python2.7/site-packages/django/core/management/base.py", line 359, in check
    include_deployment_checks=include_deployment_checks,
  File "/Users/catalinaene/Desktop/myEnvironments/djangoEnv/lib/python2.7/site-packages/django/core/management/base.py", line 346, in _run_checks
    return checks.run_checks(**kwargs)
  File "/Users/catalinaene/Desktop/myEnvironments/djangoEnv/lib/python2.7/site-packages/django/core/checks/registry.py", line 81, in run_checks
    new_errors = check(app_configs=app_configs)
  File "/Users/catalinaene/Desktop/myEnvironments/djangoEnv/lib/python2.7/site-packages/django/core/checks/urls.py", line 16, in check_url_config
    return check_resolver(resolver)
  File "/Users/catalinaene/Desktop/myEnvironments/djangoEnv/lib/python2.7/site-packages/django/core/checks/urls.py", line 26, in check_resolver
    return check_method()
  File "/Users/catalinaene/Desktop/myEnvironments/djangoEnv/lib/python2.7/site-packages/django/urls/resolvers.py", line 254, in check
    for pattern in self.url_patterns:
  File "/Users/catalinaene/Desktop/myEnvironments/djangoEnv/lib/python2.7/site-packages/django/utils/functional.py", line 35, in __get__
    res = instance.__dict__[self.name] = self.func(instance)
  File "/Users/catalinaene/Desktop/myEnvironments/djangoEnv/lib/python2.7/site-packages/django/urls/resolvers.py", line 405, in url_patterns
    patterns = getattr(self.urlconf_module, "urlpatterns", self.urlconf_module)
  File "/Users/catalinaene/Desktop/myEnvironments/djangoEnv/lib/python2.7/site-packages/django/utils/functional.py", line 35, in __get__
    res = instance.__dict__[self.name] = self.func(instance)
  File "/Users/catalinaene/Desktop/myEnvironments/djangoEnv/lib/python2.7/site-packages/django/urls/resolvers.py", line 398, in urlconf_module
    return import_module(self.urlconf_name)
  File "/System/Library/Frameworks/Python.framework/Versions/2.7/lib/python2.7/importlib/__init__.py", line 37, in import_module
    __import__(name)
  File "/Users/catalinaene/Desktop/Assignments/PythonStack/Django/Users/Users/urls.py", line 20, in <module>
    url(r'^', include('apps.users_app.url')),
  File "/Users/catalinaene/Desktop/myEnvironments/djangoEnv/lib/python2.7/site-packages/django/conf/urls/__init__.py", line 50, in include
    urlconf_module = import_module(urlconf_module)
  File "/System/Library/Frameworks/Python.framework/Versions/2.7/lib/python2.7/importlib/__init__.py", line 37, in import_module
    __import__(name)
ImportError: No module named url
(djangoEnv) Catalinas-MacBook-Pro:USers catalinaene$ python manage.py makemigrations
Traceback (most recent call last):
  File "manage.py", line 22, in <module>
    execute_from_command_line(sys.argv)
  File "/Users/catalinaene/Desktop/myEnvironments/djangoEnv/lib/python2.7/site-packages/django/core/management/__init__.py", line 364, in execute_from_command_line
    utility.execute()
  File "/Users/catalinaene/Desktop/myEnvironments/djangoEnv/lib/python2.7/site-packages/django/core/management/__init__.py", line 356, in execute
    self.fetch_command(subcommand).run_from_argv(self.argv)
  File "/Users/catalinaene/Desktop/myEnvironments/djangoEnv/lib/python2.7/site-packages/django/core/management/base.py", line 283, in run_from_argv
    self.execute(*args, **cmd_options)
  File "/Users/catalinaene/Desktop/myEnvironments/djangoEnv/lib/python2.7/site-packages/django/core/management/base.py", line 327, in execute
    self.check()
  File "/Users/catalinaene/Desktop/myEnvironments/djangoEnv/lib/python2.7/site-packages/django/core/management/base.py", line 359, in check
    include_deployment_checks=include_deployment_checks,
  File "/Users/catalinaene/Desktop/myEnvironments/djangoEnv/lib/python2.7/site-packages/django/core/management/base.py", line 346, in _run_checks
    return checks.run_checks(**kwargs)
  File "/Users/catalinaene/Desktop/myEnvironments/djangoEnv/lib/python2.7/site-packages/django/core/checks/registry.py", line 81, in run_checks
    new_errors = check(app_configs=app_configs)
  File "/Users/catalinaene/Desktop/myEnvironments/djangoEnv/lib/python2.7/site-packages/django/core/checks/urls.py", line 16, in check_url_config
    return check_resolver(resolver)
  File "/Users/catalinaene/Desktop/myEnvironments/djangoEnv/lib/python2.7/site-packages/django/core/checks/urls.py", line 26, in check_resolver
    return check_method()
  File "/Users/catalinaene/Desktop/myEnvironments/djangoEnv/lib/python2.7/site-packages/django/urls/resolvers.py", line 254, in check
    for pattern in self.url_patterns:
  File "/Users/catalinaene/Desktop/myEnvironments/djangoEnv/lib/python2.7/site-packages/django/utils/functional.py", line 35, in __get__
    res = instance.__dict__[self.name] = self.func(instance)
  File "/Users/catalinaene/Desktop/myEnvironments/djangoEnv/lib/python2.7/site-packages/django/urls/resolvers.py", line 405, in url_patterns
    patterns = getattr(self.urlconf_module, "urlpatterns", self.urlconf_module)
  File "/Users/catalinaene/Desktop/myEnvironments/djangoEnv/lib/python2.7/site-packages/django/utils/functional.py", line 35, in __get__
    res = instance.__dict__[self.name] = self.func(instance)
  File "/Users/catalinaene/Desktop/myEnvironments/djangoEnv/lib/python2.7/site-packages/django/urls/resolvers.py", line 398, in urlconf_module
    return import_module(self.urlconf_name)
  File "/System/Library/Frameworks/Python.framework/Versions/2.7/lib/python2.7/importlib/__init__.py", line 37, in import_module
    __import__(name)
  File "/Users/catalinaene/Desktop/Assignments/PythonStack/Django/Users/Users/urls.py", line 20, in <module>
    url(r'^', include('apps.users_app.urls')),
  File "/Users/catalinaene/Desktop/myEnvironments/djangoEnv/lib/python2.7/site-packages/django/conf/urls/__init__.py", line 50, in include
    urlconf_module = import_module(urlconf_module)
  File "/System/Library/Frameworks/Python.framework/Versions/2.7/lib/python2.7/importlib/__init__.py", line 37, in import_module
    __import__(name)
  File "/Users/catalinaene/Desktop/Assignments/PythonStack/Django/Users/apps/users_app/urls.py", line 2, in <module>
    from . import views
  File "/Users/catalinaene/Desktop/Assignments/PythonStack/Django/Users/apps/users_app/views.py", line 4, in <module>
    from django.shortcuts import render, request, redirect
ImportError: cannot import name request
(djangoEnv) Catalinas-MacBook-Pro:USers catalinaene$ python manage.py makemigrations
Migrations for 'users_app':
  apps/users_app/migrations/0002_auto_20171016_2100.py
    - Add field updated_at to user
    - Alter field created_at on user
(djangoEnv) Catalinas-MacBook-Pro:USers catalinaene$ python manage.py migrate
Operations to perform:
  Apply all migrations: admin, auth, contenttypes, sessions, users_app
Running migrations:
  Applying users_app.0001_initial... OK
  Applying users_app.0002_auto_20171016_2100... OK
(djangoEnv) Catalinas-MacBook-Pro:USers catalinaene$ python manage.py shell
Python 2.7.10 (default, Feb  7 2017, 00:08:15) 
[GCC 4.2.1 Compatible Apple LLVM 8.0.0 (clang-800.0.34)] on darwin
Type "help", "copyright", "credits" or "license" for more information.
(InteractiveConsole)
>>> from apps.users_app.models import *
>>> user.objects.create(first_name="Catalina",last_name="Ene",email_address="cat@gmail.com",age=23)
<user: user object>
>>> user.objects.create(first_name="Jenna",last_name="Kendall",email_address="jenna@gmail.com",age=32)
<user: user object>
>>> user.objects.all()
<QuerySet [<user: user object>, <user: user object>]>
>>> user.objects.first()
<user: user object>
>>> b.first_name
Traceback (most recent call last):
  File "<console>", line 1, in <module>
NameError: name 'b' is not defined
>>> user.objects.count()
2
>>>  user.objects.create(first_name="Jenna",last_name="Kendall",email_address="jenna@gmail.com",age=32)
  File "<console>", line 1
    user.objects.create(first_name="Jenna",last_name="Kendall",email_address="jenna@gmail.com",age=32)
    ^
IndentationError: unexpected indent
>>> user.objects.create(first_name="Alan",last_name="Smith",email_address="alansmith@gmail.com",age=48)
<user: user object>
>>> user.objects.create(first_name="Marco",last_name="Ciotti",email_address="marcoc@gmail.com",age=42)
<user: user object>
>>> user.objects.last()
<user: user object>
>>> user.objects.all().order_by("first_name")
<QuerySet [<user: user object>, <user: user object>, <user: user object>, <user: user object>]>
>>> user.objects.get(id=3)
<user: user object>
>>> b = user.objects.get(id=3)
>>> user.objects.filter(first_name="Alan")
<QuerySet [<user: user object>]>
>>> >>> user.objects.all().values
<bound method QuerySet.values of <QuerySet [<user: user object>, <user: user object>, <user: user object>, <user: user object>]>>
>>> exit()
(djangoEnv) Catalinas-MacBook-Pro:USers catalinaene$ python manage.py makemigrations
No changes detected
(djangoEnv) Catalinas-MacBook-Pro:USers catalinaene$ python manage.py migrate
Operations to perform:
  Apply all migrations: admin, auth, contenttypes, sessions, users_app
Running migrations:
  No migrations to apply.
(djangoEnv) Catalinas-MacBook-Pro:USers catalinaene$ python manage.py shell
Python 2.7.10 (default, Feb  7 2017, 00:08:15) 
[GCC 4.2.1 Compatible Apple LLVM 8.0.0 (clang-800.0.34)] on darwin
Type "help", "copyright", "credits" or "license" for more information.
(InteractiveConsole)
>>> from apps.users_app.models import users
Traceback (most recent call last):
  File "<console>", line 1, in <module>
ImportError: cannot import name users
>>> from apps.users_app.models import *
>>> user.objects.first()
Traceback (most recent call last):
  File "<console>", line 1, in <module>
  File "/Users/catalinaene/Desktop/myEnvironments/djangoEnv/lib/python2.7/site-packages/django/db/models/base.py", line 590, in __repr__
    u = six.text_type(self)
  File "/Users/catalinaene/Desktop/Assignments/PythonStack/Django/Users/apps/users_app/models.py", line 15, in __str__
    return self.email
AttributeError: 'user' object has no attribute 'email'
>>> user.objects.first()
Traceback (most recent call last):
  File "<console>", line 1, in <module>
  File "/Users/catalinaene/Desktop/myEnvironments/djangoEnv/lib/python2.7/site-packages/django/db/models/base.py", line 590, in __repr__
    u = six.text_type(self)
  File "/Users/catalinaene/Desktop/Assignments/PythonStack/Django/Users/apps/users_app/models.py", line 15, in __str__
    return self.first_name, self.last_name, self.email_address, self.age
AttributeError: 'user' object has no attribute 'email'
>>> user.objects.first()
Traceback (most recent call last):
  File "<console>", line 1, in <module>
  File "/Users/catalinaene/Desktop/myEnvironments/djangoEnv/lib/python2.7/site-packages/django/db/models/base.py", line 590, in __repr__
    u = six.text_type(self)
  File "/Users/catalinaene/Desktop/Assignments/PythonStack/Django/Users/apps/users_app/models.py", line 15, in __str__
    #     return self.first_name, self.last_name, self.email_address, self.age
AttributeError: 'user' object has no attribute 'email'
>>> exit
Use exit() or Ctrl-D (i.e. EOF) to exit
>>> exit()
(djangoEnv) Catalinas-MacBook-Pro:USers catalinaene$ python manage.py migrations
Unknown command: 'migrations'
Type 'manage.py help' for usage.
(djangoEnv) Catalinas-MacBook-Pro:USers catalinaene$ python manage.py makemigrations
No changes detected
(djangoEnv) Catalinas-MacBook-Pro:USers catalinaene$ python manage.py migrate 
Operations to perform:
  Apply all migrations: admin, auth, contenttypes, sessions, users_app
Running migrations:
  No migrations to apply.
(djangoEnv) Catalinas-MacBook-Pro:USers catalinaene$ python manage.py shell
Python 2.7.10 (default, Feb  7 2017, 00:08:15) 
[GCC 4.2.1 Compatible Apple LLVM 8.0.0 (clang-800.0.34)] on darwin
Type "help", "copyright", "credits" or "license" for more information.
(InteractiveConsole)
>>> from app.users_app.models import *
Traceback (most recent call last):
  File "<console>", line 1, in <module>
ImportError: No module named app.users_app.models
>>> from apps.users_app.models import *
>>> user.objects.first().first_name
u'Catalina'
>>> user.objects.order_by("first_name).first_name
  File "<console>", line 1
    user.objects.order_by("first_name).first_name
                                                ^
SyntaxError: EOL while scanning string literal
>>> user.objects.order_by("first_name)
  File "<console>", line 1
    user.objects.order_by("first_name)
                                     ^
SyntaxError: EOL while scanning string literal
>>> user.objects.order_by("first_name")
<QuerySet [<user: user object>, <user: user object>, <user: user object>, <user: user object>]>
>>> user.objects.order_by("first_name").first_name
Traceback (most recent call last):
  File "<console>", line 1, in <module>
AttributeError: 'QuerySet' object has no attribute 'first_name'
>>> user.objects.order_by("first_name").value("first_name")
Traceback (most recent call last):
  File "<console>", line 1, in <module>
AttributeError: 'QuerySet' object has no attribute 'value'
>>> user.objects.order_by("first_name").
  File "<console>", line 1
    user.objects.order_by("first_name").
                                       ^
SyntaxError: invalid syntax
>>> user.objects.order_by("first_name")
<QuerySet [<user: user object>, <user: user object>, <user: user object>, <user: user object>]>
>>> user.objects.first_name
Traceback (most recent call last):
  File "<console>", line 1, in <module>
AttributeError: 'Manager' object has no attribute 'first_name'
>>> user.objects.get(id=3)
<user: user object>
>>>  user3.last_name = "polo"
  File "<console>", line 1
    user3.last_name = "polo"
    ^
IndentationError: unexpected indent
>>> user.objects.last_name="polo"
>>> user.objects.save
Traceback (most recent call last):
  File "<console>", line 1, in <module>
AttributeError: 'Manager' object has no attribute 'save'
>>> user3.objects.save
Traceback (most recent call last):
  File "<console>", line 1, in <module>
NameError: name 'user3' is not defined
>>> user.objects.get(id=3)
<user: user object>
>>> b=user.objects.get(id=3)
>>> b.first_name = "polo"
>>> b.save()
>>> user.objects.get(id=2).delete
<bound method user.delete of <user: user object>>
>>> 
>>> b=user.objects.get(id=4)
>>> b.delete()
(1, {u'users_app.user': 1})
>>> 
